2023-03-02 23:42:58 align.main INFO : Reading netlist: /home/kevin/Downloads/msvsd3bitfadc/week3/align-counter/counter/counter.sp subckt=COUNTER, flat=0
2023-03-02 23:42:58 align.compiler.compiler INFO : Starting topology identification...
2023-03-02 23:42:58 align.cmdline ERROR : Fatal Error. Cannot proceed
Traceback (most recent call last):
  File "/home/kevin/ALIGN-public/general/lib/python3.10/site-packages/align/schema/parser.py", line 167, in _process_instance
    self._scope[-1].elements.append(Instance(name=name, model=model.name,
  File "/home/kevin/ALIGN-public/general/lib/python3.10/site-packages/align/schema/types.py", line 75, in __init__
    super().__init__(*args, **kwargs)
  File "pydantic/main.py", line 342, in pydantic.main.BaseModel.__init__
pydantic.error_wrappers.ValidationError: 1 validation error for Instance
name
  X1 does not start with C (type=assertion_error)

During handling of the above exception, another exception occurred:

Traceback (most recent call last):
  File "/home/kevin/ALIGN-public/general/lib/python3.10/site-packages/align/cmdline.py", line 176, in parse_args
    return schematic2layout(**vars(arguments))
  File "/home/kevin/ALIGN-public/general/lib/python3.10/site-packages/align/main.py", line 164, in schematic2layout
    primitive_lib = generate_hierarchy(netlist, subckt, topology_dir, flatten, pdk_dir)
  File "/home/kevin/ALIGN-public/general/lib/python3.10/site-packages/align/compiler/compiler.py", line 27, in generate_hierarchy
    ckt_data, primitive_library = compiler_input(
  File "/home/kevin/ALIGN-public/general/lib/python3.10/site-packages/align/compiler/compiler.py", line 76, in compiler_input
    ckt_parser.parse(lines)
  File "/home/kevin/ALIGN-public/general/lib/python3.10/site-packages/align/schema/parser.py", line 88, in parse
    self._dispatch(cache)
  File "/home/kevin/ALIGN-public/general/lib/python3.10/site-packages/align/schema/parser.py", line 106, in _dispatch
    self._process_instance(token.value.upper(), args, kwargs)
  File "/home/kevin/ALIGN-public/general/lib/python3.10/site-packages/align/schema/parser.py", line 171, in _process_instance
    assert False, f"could not identify device parameters {name} {kwargs} \
AssertionError: could not identify device parameters X1 {}                     allowed parameters of model SKY130_FD_PR__CAP_MIM_M3_1 are {'VALUE': '0', 'PARALLEL': '1', 'STACK': '1', 'M': '1', 'L': '1', 'W': '1'}
