2023-02-18 18:22:07 align.main INFO : Reading netlist: /home/kevin/Documents/msvsd3bitfadc/week1/align-section7/section7/section7.sp subckt=SECTION7, flat=0
2023-02-18 18:22:07 align.compiler.compiler INFO : Starting topology identification...
2023-02-18 18:22:07 align.cmdline ERROR : Fatal Error. Cannot proceed
Traceback (most recent call last):
  File "/home/kevin/ALIGN-public/general/lib/python3.10/site-packages/align/schema/parser.py", line 167, in _process_instance
    self._scope[-1].elements.append(Instance(name=name, model=model.name,
  File "/home/kevin/ALIGN-public/general/lib/python3.10/site-packages/align/schema/types.py", line 75, in __init__
    super().__init__(*args, **kwargs)
  File "pydantic/main.py", line 342, in pydantic.main.BaseModel.__init__
pydantic.error_wrappers.ValidationError: 1 validation error for Instance
parameters
  Instance parameters must be a subset of Model parameters (type=assertion_error)

During handling of the above exception, another exception occurred:

Traceback (most recent call last):
  File "/home/kevin/ALIGN-public/general/lib/python3.10/site-packages/align/cmdline.py", line 176, in parse_args
    return schematic2layout(**vars(arguments))
  File "/home/kevin/ALIGN-public/general/lib/python3.10/site-packages/align/main.py", line 164, in schematic2layout
    primitive_lib = generate_hierarchy(netlist, subckt, topology_dir, flatten, pdk_dir)
  File "/home/kevin/ALIGN-public/general/lib/python3.10/site-packages/align/compiler/compiler.py", line 27, in generate_hierarchy
    ckt_data, primitive_library = compiler_input(
  File "/home/kevin/ALIGN-public/general/lib/python3.10/site-packages/align/compiler/compiler.py", line 76, in compiler_input
    ckt_parser.parse(lines)
  File "/home/kevin/ALIGN-public/general/lib/python3.10/site-packages/align/schema/parser.py", line 88, in parse
    self._dispatch(cache)
  File "/home/kevin/ALIGN-public/general/lib/python3.10/site-packages/align/schema/parser.py", line 106, in _dispatch
    self._process_instance(token.value.upper(), args, kwargs)
  File "/home/kevin/ALIGN-public/general/lib/python3.10/site-packages/align/schema/parser.py", line 171, in _process_instance
    assert False, f"could not identify device parameters {name} {kwargs} \
AssertionError: could not identify device parameters M0 {'AD': 1.02, 'PD': 4.6, 'AS': 2.04, 'PS': 9.2, 'W': 1.7, 'L': 0.19999999999999998}                     allowed parameters of model SKY130_FD_PR__PFET_01V8 are {'W': '1', 'L': '1', 'NFIN': '1', 'NF': '2', 'M': '1', 'PARALLEL': '1', 'STACK': '1'}
